<sdf version='1.7'>
  <model name='robot'>
    <link name='base'>
      <inertial>
        <pose>0 0 0 0 -0 0</pose>
        <mass>31.5</mass>
        <inertia>
          <ixx>0.00506133</ixx>
          <ixy>0</ixy>
          <ixz>0</ixz>
          <iyy>0.00506133</iyy>
          <iyz>0</iyz>
          <izz>0.00293333</izz>
        </inertia>
      </inertial>
      <collision name='base_collision'>
        <pose>0 0 0 0 -0 0</pose>
        <geometry>
          <box>
            <size>0.2 0.2 0.3</size>
          </box>
        </geometry>
        <surface>
          <contact>
            <ode>
              <kp>1e+06</kp>
              <kd>1e+06</kd>
            </ode>
          </contact>
          <friction>
            <ode>
              <mu>100</mu>
              <mu2>100</mu2>
            </ode>
          </friction>
        </surface>
      </collision>
      <visual name='base_visual'>
        <pose>0 0 0 0 -0 0</pose>
        <geometry>
          <box>
            <size>0.2 0.2 0.3</size>
          </box>
        </geometry>
        <material>
          <script>
            <name>Gazebo/Green</name>
            <uri>file://media/materials/scripts/gazebo.material</uri>
          </script>
        </material>
      </visual>
    </link>
    <joint name='haa_joint' type='revolute'>
      <pose relative_to='base'>0 0 -0.15 2.03444 1.5708 -1.10715</pose>
      <parent>base</parent>
      <child>hipassembly</child>
      <axis>
        <xyz>0 0 1</xyz>
        <limit>
          <lower>-1.6</lower>
          <upper>1.6</upper>
          <effort>1e+07</effort>
          <velocity>0.7</velocity>
        </limit>
        <dynamics>
          <spring_reference>0</spring_reference>
          <spring_stiffness>0</spring_stiffness>
        </dynamics>
      </axis>
    </joint>
    <link name='hipassembly'>
      <pose relative_to='haa_joint'>0 0 0 0 -0 0</pose>
      <inertial>
        <pose>0 0 0 0 -0 0</pose>
        <mass>7.5</mass>
        <inertia>
          <ixx>0.00140907</ixx>
          <ixy>0</ixy>
          <ixz>0</ixz>
          <iyy>0.0015296</iyy>
          <iyz>0</iyz>
          <izz>0.000218659</izz>
        </inertia>
      </inertial>
      <collision name='hipassembly_collision'>
        <pose>0 0 0 0 -0 0</pose>
        <geometry>
          <mesh>
            <scale>1 1 1</scale>
            <uri>model://description/meshes/leg/hipassembly.dae</uri>
          </mesh>
        </geometry>
        <surface>
          <contact>
            <ode>
              <kp>1e+06</kp>
              <kd>1e+06</kd>
            </ode>
          </contact>
          <friction>
            <ode>
              <mu>100</mu>
              <mu2>100</mu2>
            </ode>
          </friction>
        </surface>
      </collision>
      <visual name='hipassembly_visual'>
        <pose>0 0 0 0 -0 0</pose>
        <geometry>
          <mesh>
            <scale>1 1 1</scale>
            <uri>model://description/meshes/leg/hipassembly.dae</uri>
          </mesh>
        </geometry>
      </visual>
    </link>
    <joint name='hfe_joint' type='revolute'>
      <pose relative_to='hipassembly'>0.08 0 0 1.5708 -0 0</pose>
      <parent>hipassembly</parent>
      <child>upperleg</child>
      <axis>
        <xyz>0 0 1</xyz>
        <limit>
          <lower>-1.6</lower>
          <upper>1.6</upper>
          <effort>1e+07</effort>
          <velocity>0.7</velocity>
        </limit>
        <dynamics>
          <spring_reference>0</spring_reference>
          <spring_stiffness>0</spring_stiffness>
        </dynamics>
      </axis>
    </joint>
    <link name='upperleg'>
      <pose relative_to='hfe_joint'>0 0 0 0 -0 0</pose>
      <inertial>
        <pose>0 0 0 0 -0 0</pose>
        <mass>7.5</mass>
        <inertia>
          <ixx>0.000119503</ixx>
          <ixy>0</ixy>
          <ixz>0</ixz>
          <iyy>0.00158479</iyy>
          <iyz>0</iyz>
          <izz>0.00158586</izz>
        </inertia>
      </inertial>
      <collision name='upperleg_collision'>
        <pose>0 0 0 0 -0 0</pose>
        <geometry>
          <mesh>
            <scale>1 1 1</scale>
            <uri>model://description/meshes/leg/upperleg.dae</uri>
          </mesh>
        </geometry>
        <surface>
          <contact>
            <ode>
              <kp>1e+06</kp>
              <kd>1e+06</kd>
            </ode>
          </contact>
          <friction>
            <ode>
              <mu>100</mu>
              <mu2>100</mu2>
            </ode>
          </friction>
        </surface>
      </collision>
      <visual name='upperleg_visual'>
        <pose>0 0 0 0 -0 0</pose>
        <geometry>
          <mesh>
            <scale>1 1 1</scale>
            <uri>model://description/meshes/leg/upperleg.dae</uri>
          </mesh>
        </geometry>
      </visual>
    </link>
    <joint name='kfe_joint' type='revolute'>
      <pose relative_to='upperleg'>0.35 0 0 0 -0 0</pose>
      <parent>upperleg</parent>
      <child>lowerleg</child>
      <axis>
        <xyz>0 0 1</xyz>
        <limit>
          <lower>-1.6</lower>
          <upper>0</upper>
          <effort>1e+07</effort>
          <velocity>0.7</velocity>
        </limit>
        <dynamics>
          <spring_reference>0</spring_reference>
          <spring_stiffness>0</spring_stiffness>
        </dynamics>
      </axis>
    </joint>
    <link name='lowerleg'>
      <pose relative_to='kfe_joint'>0 0 0 0 -0 0</pose>
      <inertial>
        <pose>0.101818 0 0 0 -0 0</pose>
        <mass>2.75</mass>
        <inertia>
          <ixx>1.86954e-05</ixx>
          <ixy>0</ixy>
          <ixz>0</ixz>
          <iyy>0.0698631</iyy>
          <iyz>0</iyz>
          <izz>0.069856</izz>
        </inertia>
      </inertial>
      <collision name='lowerleg_collision'>
        <pose>0 0 0 0 -0 0</pose>
        <geometry>
          <mesh>
            <scale>1 1 1</scale>
            <uri>model://description/meshes/leg/lowerleg.dae</uri>
          </mesh>
        </geometry>
        <surface>
          <contact>
            <ode>
              <kp>1e+06</kp>
              <kd>1e+06</kd>
            </ode>
          </contact>
          <friction>
            <ode>
              <mu>100</mu>
              <mu2>100</mu2>
            </ode>
          </friction>
        </surface>
      </collision>
      <collision name='lowerleg_fixed_joint_lump__contactsensor_link_collision_1'>
        <pose>0.35 0 0 0 -0 0</pose>
        <geometry>
          <sphere>
            <radius>0.08</radius>
          </sphere>
        </geometry>
        <surface>
          <contact>
            <ode>
              <kp>1e+06</kp>
              <kd>1e+06</kd>
            </ode>
          </contact>
          <friction>
            <ode>
              <mu>1e+06</mu>
              <mu2>1e+06</mu2>
            </ode>
          </friction>
        </surface>
      </collision>
      <visual name='lowerleg_visual'>
        <pose>0 0 0 0 -0 0</pose>
        <geometry>
          <mesh>
            <scale>1 1 1</scale>
            <uri>model://description/meshes/leg/lowerleg.dae</uri>
          </mesh>
        </geometry>
      </visual>
      <visual name='lowerleg_fixed_joint_lump__contactsensor_link_visual_1'>
        <pose>0.35 0 0 0 -0 0</pose>
        <geometry>
          <sphere>
            <radius>0.08</radius>
          </sphere>
        </geometry>
        <material>
          <script>
            <name>Gazebo/Blue</name>
            <uri>file://media/materials/scripts/gazebo.material</uri>
          </script>
        </material>
      </visual>
      <sensor name='contactsensor_sensor' type='contact'>
        <always_on>1</always_on>
        <contact>
          <collision>lowerleg_fixed_joint_lump__contactsensor_link_collision_1</collision>
          <topic>__default_topic__</topic>
        </contact>
        <plugin name='bumper0_plugin' filename='libgazebo_ros_bumper.so'>
          <bumperTopicName>lowerleg_contactsensor_state</bumperTopicName>
          <frameName>contactsensor_link</frameName>
        </plugin>
        <pose>0.35 0 0 0 -0 0</pose>
      </sensor>
    </link>
  </model>
</sdf>
